2022-12-11 15:09:01,715 (51720/MainThread) litecli.main ERROR - sql: 'clear', error: OperationalError('near "clear": syntax error')
2022-12-11 15:09:01,716 (51720/MainThread) litecli.main ERROR - traceback: 'Traceback (most recent call last):\n  File "/opt/homebrew/lib/python3.10/site-packages/litecli/sqlexecute.py", line 129, in run\n    for result in special.execute(cur, sql):\n  File "/opt/homebrew/lib/python3.10/site-packages/litecli/packages/special/main.py", line 109, in execute\n    raise CommandNotFound\nlitecli.packages.special.main.CommandNotFound\n\nDuring handling of the above exception, another exception occurred:\n\nTraceback (most recent call last):\n  File "/opt/homebrew/lib/python3.10/site-packages/litecli/main.py", line 447, in one_iteration\n    for title, cur, headers, status in res:\n  File "/opt/homebrew/lib/python3.10/site-packages/litecli/sqlexecute.py", line 133, in run\n    cur.execute(sql)\nsqlite3.OperationalError: near "clear": syntax error\n'
2022-12-11 15:17:06,507 (52624/MainThread) litecli.main ERROR - sql: '.databases', error: OperationalError('Not connected to database.')
2022-12-11 15:17:06,509 (52624/MainThread) litecli.main ERROR - traceback: 'Traceback (most recent call last):\n  File "/opt/homebrew/lib/python3.10/site-packages/litecli/main.py", line 447, in one_iteration\n    for title, cur, headers, status in res:\n  File "/opt/homebrew/lib/python3.10/site-packages/litecli/sqlexecute.py", line 122, in run\n    raise OperationalError("Not connected to database.")\nsqlite3.OperationalError: Not connected to database.\n'
2022-12-16 18:45:13,357 (30717/MainThread) litecli.main ERROR - sql: '.databases', error: OperationalError('Not connected to database.')
2022-12-16 18:45:13,359 (30717/MainThread) litecli.main ERROR - traceback: 'Traceback (most recent call last):\n  File "/opt/homebrew/lib/python3.10/site-packages/litecli/main.py", line 447, in one_iteration\n    for title, cur, headers, status in res:\n  File "/opt/homebrew/lib/python3.10/site-packages/litecli/sqlexecute.py", line 122, in run\n    raise OperationalError("Not connected to database.")\nsqlite3.OperationalError: Not connected to database.\n'
2023-01-02 18:25:22,768 (13908/MainThread) litecli.main ERROR - sql: '.databases', error: OperationalError('Not connected to database.')
2023-01-02 18:25:22,770 (13908/MainThread) litecli.main ERROR - traceback: 'Traceback (most recent call last):\n  File "/opt/homebrew/lib/python3.10/site-packages/litecli/main.py", line 447, in one_iteration\n    for title, cur, headers, status in res:\n  File "/opt/homebrew/lib/python3.10/site-packages/litecli/sqlexecute.py", line 122, in run\n    raise OperationalError("Not connected to database.")\nsqlite3.OperationalError: Not connected to database.\n'
2023-01-02 18:25:43,489 (13908/MainThread) litecli.main ERROR - sql: '.help', error: OperationalError('Not connected to database.')
2023-01-02 18:25:43,490 (13908/MainThread) litecli.main ERROR - traceback: 'Traceback (most recent call last):\n  File "/opt/homebrew/lib/python3.10/site-packages/litecli/main.py", line 447, in one_iteration\n    for title, cur, headers, status in res:\n  File "/opt/homebrew/lib/python3.10/site-packages/litecli/sqlexecute.py", line 122, in run\n    raise OperationalError("Not connected to database.")\nsqlite3.OperationalError: Not connected to database.\n'
2023-01-02 18:25:45,812 (13908/MainThread) litecli.main ERROR - sql: '.help', error: OperationalError('Not connected to database.')
2023-01-02 18:25:45,813 (13908/MainThread) litecli.main ERROR - traceback: 'Traceback (most recent call last):\n  File "/opt/homebrew/lib/python3.10/site-packages/litecli/main.py", line 447, in one_iteration\n    for title, cur, headers, status in res:\n  File "/opt/homebrew/lib/python3.10/site-packages/litecli/sqlexecute.py", line 122, in run\n    raise OperationalError("Not connected to database.")\nsqlite3.OperationalError: Not connected to database.\n'
